Workbook

Sheet Istruzioni
A1: Libreria blocchi di allenamento – Nuoto e Pallanuoto
A3: Come è fatto questo file
A4: • Foglio «Blocchi»: un blocco per riga (titolo, sport, fase, obiettivo, livelli, attrezzi, stato).
A5: • Foglio «Parti»: le serie di ogni blocco, una per riga, collegate al blocco tramite l'ID (colonna A). È il dettaglio che l'app importa.
A6: • Foglio «Legenda»: zone di intensità, elenchi dei valori ammessi e il passo medio usato per stimare la durata.
A8: Come modificarlo
A9: • Puoi cambiare, aggiungere o cancellare qualsiasi riga. Le colonne con sfondo grigio (Metri totali, Durata stimata) si calcolano da sole: non scriverci dentro.
A10: • Nuovo blocco: aggiungi una riga in «Blocchi» con un ID nuovo (es. N-300, P-120) e una o più righe in «Parti» con lo stesso ID.
A11: • Giri = quante volte si ripete il gruppo di parti (es. 4x(3x100) → Giri 4, Ripetizioni 3, Distanza 100).
A12: • Lavori a tempo (pallanuoto, gambe, a secco): lascia vuota la Distanza e compila la Durata in secondi.
A13: • Recupero in secondi: è la pausa indicativa. Le ripartenze precise le calcola l'app dai test degli atleti e dalla zona.
A14: • La colonna «Descrizione» è un riassunto da leggere: se cambi le Parti, aggiornala a mano (fa fede il foglio Parti).
... A22: Nota: è una libreria di base generica, da adattare al tuo metodo. Zone, recuperi e livelli sono indicativi.

Sheet Blocchi
A1: ID | B1: Sport | C1: Fase | D1: Obiettivo | E1: Zone | F1: Titolo | G1: Descrizione | H1: Stile principale | I1: Livelli / categorie | J1: Attrezzi | K1: Metri totali | L1: Durata stimata (min) | M1: Note per l'allenatore | N1: Stato | O1: Fonte
A2: N-001 | B2: Entrambi | C2: Riscaldamento | D2: Recupero | E2: A1 | F2: 400 misto sciolto | G2: 200 SL sciolto [A1] + 100 DO sciolto [A1] + 100 RA sciolto [A1] | H2: Vari | I2: Ragazzi, Assoluti, Master | K2: =SUMPRODUCT((Parti!$A$2:$A$3000=A2)*Parti!$C$2:$C$3000*Parti!$D$2:$D$3000*Parti!$E$2:$E$3000) -> 400 | L2: =ROUND((K2*Legenda!$H$2/100+SUMPRODUCT((Parti!$A$2:$A$3000=A2)*Parti!$C$2:$C$3000*Parti!$D$2:$D$3000*(Parti!$F$2:$F$3000+Parti!$J$2:$J$3000)))/60,0) -> 7 | N2: approvato | O2: Libreria base
A3: N-002 | B3: Entrambi | C3: Riscaldamento | D3: Aerobico | E3: A1 | F3: 300 SL respirazione 3-5-7 | G3: 3x100 SL respirazione ogni 3-5-7 bracciate per 25 [A1] rec 10" | H3: Stile libero | I3: Ragazzi, Assoluti, Master | K3: =SUMPRODUCT((Parti!$A$2:$A$3000=A3)*Parti!$C$2:$C$3000*Parti!$D$2:$D$3000*Parti!$E$2:$E$3000) -> 300 | L3: =ROUND((K3*Legenda!$H$2/100+SUMPRODUCT((Parti!$A$2:$A$3000=A3)*Parti!$C$2:$C$3000*Parti!$D$2:$D$3000*(Parti!$F$2:$F$3000+Parti!$J$2:$J$3000)))/60,0) -> 6 | N3: approvato | O3: Libreria base
A4: N-003 | B4: Entrambi | C4: Riscaldamento | D4: Aerobico | E4: A1 | F4: 8x50 misti ordine inverso | G4: 8x50 MX 25 stile + 25 stile successivo, ordine inverso [A1] rec 15" | H4: Misti | I4: Ragazzi, Assoluti | K4: =SUMPRODUCT((Parti!$A$2:$A$3000=A4)*Parti!$C$2:$C$3000*Parti!$D$2:$D$3000*Parti!$E$2:$E$3000) -> 400 | L4: =ROUND((K4*Legenda!$H$2/100+SUMPRODUCT((Parti!$A$2:$A$3000=A4)*Parti!$C$2:$C$3000*Parti!$D$2:$D$3000*(Parti!$F$2:$F$3000+Parti!$J$2:$J$3000)))/60,0) -> 9 | N4: approvato | O4: Libreria base
A5: N-004 | B5: Entrambi | C5: Riscaldamento | D5: Aerobico | E5: A1 | F5: 3x200 variato | G5: 200 SL [A1] rec 20" + 200 DO [A1] rec 20" + 200 MX sciolto [A1] | H5: Vari | I5: Ragazzi, Assoluti | K5: =SUMPRODUCT((Parti!$A$2:$A$3000=A5)*Parti!$C$2:$C$3000*Parti!$D$2:$D$3000*Parti!$E$2:$E$3000) -> 600 | L5: =ROUND((K5*Legenda!$H$2/100+SUMPRODUCT((Parti!$A$2:$A$3000=A5)*Parti!$C$2:$C$3000*Parti!$D$2:$D$3000*(Parti!$F$2:$F$3000+Parti!$J$2:$J$3000)))/60,0) -> 12 | N5: approvato | O5: Libreria base
A6: N-005 | B6: Entrambi | C6: Riscaldamento | D6: Aerobico | E6: A1 | F6: 400 SL progressivo per 100 | G6: 4x100 SL progressivo per 100 (da A1 ad A2) [A1] rec 10" | H6: Stile libero | I6: Ragazzi, Assoluti, Master | K6: =SUMPRODUCT((Parti!$A$2:$A$3000=A6)*Parti!$C$2:$C$3000*Parti!$D$2:$D$3000*Parti!$E$2:$E$3000) -> 400 | L6: =ROUND((K6*Legenda!$H$2/100+SUMPRODUCT((Parti!$A$2:$A$3000=A6)*Parti!$C$2:$C$3000*Parti!$D$2:$D$3000*(Parti!$F$2:$F$3000+Parti!$J$2:$J$3000)))/60,0) -> 8 | N6: approvato | O6: Libreria base
A7: N-006 | B7: Entrambi | C7: Riscaldamento | D7: Aerobico | E7: A1 | F7: 600 variato gambe/braccia | G7: 200 SL [A1] rec 20" + 4x50 scelta gambe [A1] rec 15" (Tavoletta) + 4x50 SL braccia [A1] rec 15" (Pull buoy) | H7: Vari | I7: Ragazzi, Assoluti | J7: Pull buoy, Tavoletta | K7: =SUMPRODUCT((Parti!$A$2:$A$3000=A7)*Parti!$C$2:$C$3000*Parti!$D$2:$D$3000*Parti!$E$2:$E$3000) -> 600 | L7: =ROUND((K7*Legenda!$H$2/100+SUMPRODUCT((Parti!$A$2:$A$3000=A7)*Parti!$C$2:$C$3000*Parti!$D$2:$D$3000*(Parti!$F$2:$F$3000+Parti!$J$2:$J$3000)))/60,0) -> 13 | N7: approvato | O7: Libreria base
A8: N-007 | B8: Entrambi | C8: Riscaldamento | D8: Aerobico | E8: A1 | F8: Riscaldamento esordienti 300 | G8: 100 SL [A1] rec 20" + 100 DO [A1] rec 20" + 4x25 scelta tecnica a scelta [A1] rec 20" | H8: Vari | I8: Esordienti | K8: =SUMPRODUCT((Parti!$A$2:$A$3000=A8)*Parti!$C$2:$C$3000*Parti!$D$2:$D$3000*Parti!$E$2:$E$3000) -> 300 | L8: =ROUND((K8*Legenda!$H$2/100+SUMPRODUCT((Parti!$A$2:$A$3000=A8)*Parti!$C$2:$C$3000*Parti!$D$2:$D$3000*(Parti!$F$2:$F$3000+Parti!$J$2:$J$3000)))/60,0) -> 8 | N8: approvato | O8: Libreria base
A9: N-008 | B9: Nuoto | C9: Riscaldamento | D9: Aerobico | E9: A1 | F9: 4x50 dorso/SL esordienti | G9: 4x50 MX 25 dorso + 25 SL [A1] rec 20" | H9: Misti | I9: Esordienti | K9: =SUMPRODUCT((Parti!$A$2:$A$3000=A9)*Parti!$C$2:$C$3000*Parti!$D$2:$D$3000*Parti!$E$2:$E$3000) -> 200 | L9: =ROUND((K9*Legenda!$H$2/100+SUMPRODUCT((Parti!$A$2:$A$3000=A9)*Parti!$C$2:$C$3000*Parti!$D$2:$D$3000*(Parti!$F$2:$F$3000+Parti!$J$2:$J$3000)))/60,0) -> 5 | N9: approvato | O9: Libreria base
A10: N-009 | B10: Entrambi | C10: Riscaldamento | D10: Aerobico | E10: A1 | F10: Riscaldamento master 500 | G10: 300 scelta sciolto [A1] rec 30" + 4x50 MX sciolto [A1] rec 20" | H10: Vari | I10: Master | K10: =SUMPRODUCT((Parti!$A$2:$A$3000=A10)*Parti!$C$2:$C$3000*Parti!$D$2:$D$3000*Parti!$E$2:$E$3000) -> 500 | L10: =ROUND((K10*Legenda!$H$2/100+SUMPRODUCT((Parti!$A$2:$A$3000=A10)*Parti!$C$2:$C$3000*Parti!$D$2:$D$3000*(Parti!$F$2:$F$3000+Parti!$J$2:$J$3000)))/60,0) -> 11 | N10: approvato | O10: Libreria base
A11: N-010 | B11: Entrambi | C11: Riscaldamento | D11: Aerobico | E11: A1 | F11: 4x100 SL + stile del giorno | G11: 4x100 MX 50 SL + 50 stile del giorno [A1] rec 15" | H11: Misti | I11: Ragazzi, Assoluti, Master | K11: =SUMPRODUCT((Parti!$A$2:$A$3000=A11)*Parti!$C$2:$C$3000*Parti!$D$2:$D$3000*Parti!$E$2:$E$3000) -> 400 | L11: =ROUND((K11*Legenda!$H$2/100+SUMPRODUCT((Parti!$A$2:$A$3000=A11)*Parti!$C$2:$C$3000*Parti!$D$2:$D$3000*(Parti!$F$2:$F$3000+Parti!$J$2:$J$3000)))/60,0) -> 8 | N11: approvato | O11: Libreria base
A12: N-011 | B12: Entrambi | C12: Riscaldamento | D12: Aerobico | E12: A1 | F12: 800 continuo variato | G12: 200 SL [A1] + 200 DO [A1] + 200 scelta gambe [A1] (Pinne) + 200 SL [A1] | H12: Vari | I12: Assoluti | J12: Pinne | K12: =SUMPRODUCT((Parti!$A$2:$A$3000=A12)*Parti!$C$2:$C$3000*Parti!$D$2:$D$3000*Parti!$E$2:$E$3000) -> 800 | L12: =ROUND((K12*Legenda!$H$2/100+SUMPRODUCT((Parti!$A$2:$A$3000=A12)*Parti!$C$2:$C$3000*Parti!$D$2:$D$3000*(Parti!$F$2:$F$3000+Parti!$J$2:$J$3000)))/60,0) -> 15 | N12: approvato | O12: Libreria base
A13: N-012 | B13: Entrambi | C13: Riscaldamento | D13: Aerobico | E13: A1 | F13: 6x100 SL/DO progressivo | G13: 6x100 MX dispari SL, pari dorso, progressivo per serie [A1] rec 15" | H13: Misti | I13: Ragazzi, Assoluti | K13: =SUMPRODUCT((Parti!$A$2:$A$3000=A13)*Parti!$C$2:$C$3000*Parti!$D$2:$D$3000*Parti!$E$2:$E$3000) -> 600 | L13: =ROUND((K13*Legenda!$H$2/100+SUMPRODUCT((Parti!$A$2:$A$3000=A13)*Parti!$C$2:$C$3000*Parti!$D$2:$D$3000*(Parti!$F$2:$F$3000+Parti!$J$2:$J$3000)))/60,0) -> 13 | N13: approvato | O13: Libreria base
A14: N-013 | B14: Nuoto | C14: Riscaldamento | D14: Tecnica | E14: A1 | F14: Riscaldamento rana | G14: 200 SL [A1] rec 20" + 4x50 RA 2 gambate 1 bracciata [A1] rec 15" + 4x50 RA nuotato [A1] rec 15" | H14: Vari | I14: Ragazzi, Assoluti, Master | K14: =SUMPRODUCT((Parti!$A$2:$A$3000=A14)*Parti!$C$2:$C$3000*Parti!$D$2:$D$3000*Parti!$E$2:$E$3000) -> 600 | L14: =ROUND((K14*Legenda!$H$2/100+SUMPRODUCT((Parti!$A$2:$A$3000=A14)*Parti!$C$2:$C$3000*Parti!$D$2:$D$3000*(Parti!$F$2:$F$3000+Parti!$J$2:$J$3000)))/60,0) -> 13 | N14: approvato | O14: Libreria base
A15: N-014 | B15: Nuoto | C15: Riscaldamento | D15: Tecnica | E15: A1 | F15: Riscaldamento delfino | G15: 300 SL [A1] rec 20" + 6x25 DF braccio singolo dx/sx [A1] rec 15" (Pinne) + 4x25 DF nuotato [A1] rec 20" | H15: Vari | I15: Ragazzi, Assoluti | J15: Pinne | K15: =SUMPRODUCT((Parti!$A$2:$A$3000=A15)*Parti!$C$2:$C$3000*Parti!$D$2:$D$3000*Parti!$E$2:$E$3000) -> 550 | L15: =ROUND((K15*Legenda!$H$2/100+SUMPRODUCT((Parti!$A$2:$A$3000=A15)*Parti!$C$2:$C$3000*Parti!$D$2:$D$3000*(Parti!$F$2:$F$3000+Parti!$J$2:$J$3000)))/60,0) -> 13 | N15: approvato | O15: Libreria base
A16: N-015 | B16: Nuoto | C16: Riscaldamento | D16: Tecnica | E16: A1 | F16: Riscaldamento dorso | G16: 200 SL [A1] rec 20" + 4x50 DO braccio singolo / doppio braccio [A1] rec 15" + 4x50 DO nuotato [A1] rec 15" | H16: Vari | I16: Ragazzi, Assoluti, Master | K16: =SUMPRODUCT((Parti!$A$2:$A$3000=A16)*Parti!$C$2:$C$3000*Parti!$D$2:$D$3000*Parti!$E$2:$E$3000) -> 600 | L16: =ROUND((K16*Legenda!$H$2/100+SUMPRODUCT((Parti!$A$2:$A$3000=A16)*Parti!$C$2:$C$3000*Parti!$D$2:$D$3000*(Parti!$F$2:$F$3000+Parti!$J$2:$J$3000)))/60,0) -> 13 | N16: approvato | O16: Libreria base
A17: N-016 | B17: Nuoto | C17: Riscaldamento | D17: Velocità | E17: A1 / A2 / RG / V | F17: Riscaldamento pre-gara | G17: 400 scelta sciolto [A1] rec 30" + 4x50 SL progressivi [A2] rec 20" + 4x25 scelta ritmo gara [RG] rec 40" + 2x15 scelta sprint dal blocco [V] rec 1' | H17: Vari | I17: Ragazzi, Assoluti | K17: =SUMPRODUCT((Parti!$A$2:$A$3000=A17)*Parti!$C$2:$C$3000*Parti!$D$2:$D$3000*Parti!$E$2:$E$3000) -> 730 | L17: =ROUND((K17*Legenda!$H$2/100+SUMPRODUCT((Parti!$A$2:$A$3000=A17)*Parti!$C$2:$C$3000*Parti!$D$2:$D$3000*(Parti!$F$2:$F$3000+Parti!$J$2:$J$3000)))/60,0) -> 20 | M17: Da usare il giorno della gara o nella seduta di rifinitura. | N17: approvato | O17: Libreria base
A18: N-017 | B18: Entrambi | C18: Riscaldamento | D18: Aerobico | E18: A1 | F18: 400 con pinne | G18: 400 MX 100 SL + 100 dorso + 100 delfino-ondulazioni + 100 SL [A1] (Pinne) | H18: Misti | I18: Ragazzi, Assoluti, Master | J18: Pinne | K18: =SUMPRODUCT((Parti!$A$2:$A$3000=A18)*Parti!$C$2:$C$3000*Parti!$D$2:$D$3000*Parti!$E$2:$E$3000) -> 400 | L18: =ROUND((K18*Legenda!$H$2/100+SUMPRODUCT((Parti!$A$2:$A$3000=A18)*Parti!$C$2:$C$3000*Parti!$D$2:$D$3000*(Parti!$F$2:$F$3000+Parti!$J$2:$J$3000)))/60,0) -> 7 | N18: approvato | O18: Libreria base
A19: N-018 | B19: Entrambi | C19: Attivazione | D19: Velocità | E19: B1 | F19: 6x25 SL progressivi | G19: 6x25 SL progressivi nella serie [B1] rec 20" | H19: Stile libero | I19: Esordienti, Ragazzi, Assoluti, Master | K19: =SUMPRODUCT((Parti!$A$2:$A$3000=A19)*Parti!$C$2:$C$3000*Parti!$D$2:$D$3000*Parti!$E$2:$E$3000) -> 150 | L19: =ROUND((K19*Legenda!$H$2/100+SUMPRODUCT((Parti!$A$2:$A$3000=A19)*Parti!$C$2:$C$3000*Parti!$D$2:$D$3000*(Parti!$F$2:$F$3000+Parti!$J$2:$J$3000)))/60,0) -> 5 | N19: approvato | O19: Libreria base
A20: N-019 | B20: Nuoto | C20: Attivazione | D20: Velocità | E20: B1 | F20: 6x25 DO progressivi | G20: 6x25 DO progressivi nella serie [B1] rec 20" | H20: Dorso | I20: Esordienti, Ragazzi, Assoluti, Master | K20: =SUMPRODUCT((Parti!$A$2:$A$3000=A20)*Parti!$C$2:$C$3000*Parti!$D$2:$D$3000*Parti!$E$2:$E$3000) -> 150 | L20: =ROUND((K20*Legenda!$H$2/100+SUMPRODUCT((Parti!$A$2:$A$3000=A20)*Parti!$C$2:$C$3000*Parti!$D$2:$D$3000*(Parti!$F$2:$F$3000+Parti!$J$2:$J$3000)))/60,0) -> 5 | N20: approvato | O20: Libreria base
A21: N-020 | B21: Nuoto | C21: Attivazione | D21: Velocità | E21: B1 | F21: 6x25 RA progressivi | G21: 6x25 RA progressivi nella serie [B1] rec 20" | H21: Rana | I21: Esordienti, Ragazzi, Assoluti, Master | K21: =SUMPRODUCT((Parti!$A$2:$A$3000=A21)*Parti!$C$2:$C$3000*Parti!$D$2:$D$3000*Parti!$E$2:$E$3000) -> 150 | L21: =ROUND((K21*Legenda!$H$2/100+SUMPRODUCT((Parti!$A$2:$A$3000=A21)*Parti!$C$2:$C$3000*Parti!$D$2:$D$3000*(Parti!$F$2:$F$3000+Parti!$J$2:$J$3000)))/60,0) -> 5 | N21: approvato | O21: Libreria base
A22: N-021 | B22: Nuoto | C22: Attivazione | D22: Velocità | E22: B1 | F22: 6x25 DF progressivi | G22: 6x25 DF progressivi nella serie [B1] rec 20" | H22: Delfino | I22: Esordienti, Ragazzi, Assoluti, Master | K22: =SUMPRODUCT((Parti!$A$2:$A$3000=A22)*Parti!$C$2:$C$3000*Parti!$D$2:$D$3000*Parti!$E$2:$E$3000) -> 150 | L22: =ROUND((K22*Legenda!$H$2/100+SUMPRODUCT((Parti!$A$2:$A$3000=A22)*Parti!$C$2:$C$3000*Parti!$D$2:$D$3000*(Parti!$F$2:$F$3000+Parti!$J$2:$J$3000)))/60,0) -> 5 | N22: approvato | O22: Libreria base
A23: N-022 | B23: Entrambi | C23: Attivazione | D23: Velocità | E23: B1 | F23: 6x25 MX progressivi | G23: 6x25 MX progressivi nella serie [B1] rec 20" | H23: Misti | I23: Esordienti, Ragazzi, Assoluti, Master | K23: =SUMPRODUCT((Parti!$A$2:$A$3000=A23)*Parti!$C$2:$C$3000*Parti!$D$2:$D$3000*Parti!$E$2:$E$3000) -> 150 | L23: =ROUND((K23*Legenda!$H$2/100+SUMPRODUCT((Parti!$A$2:$A$3000=A23)*Parti!$C$2:$C$3000*Parti!$D$2:$D$3000*(Parti!$F$2:$F$3000+Parti!$J$2:$J$3000)))/60,0) -> 5 | N23: approvato | O23: Libreria base
A24: N-023 | B24: Entrambi | C24: Attivazione | D24: Velocità | E24: B1 | F24: 4x50 SL build-up | G24: 4x50 SL crescente nella vasca [B1] rec 20" | H24: Stile libero | I24: Ragazzi, Assoluti, Master | K24: =SUMPRODUCT((Parti!$A$2:$A$3000=A24)*Parti!$C$2:$C$3000*Parti!$D$2:$D$3000*Parti!$E$2:$E$3000) -> 200 | L24: =ROUND((K24*Legenda!$H$2/100+SUMPRODUCT((Parti!$A$2:$A$3000=A24)*Parti!$C$2:$C$3000*Parti!$D$2:$D$3000*(Parti!$F$2:$F$3000+Parti!$J$2:$J$3000)))/60,0) -> 5 | N24: approvato | O24: Libreria base
A25: N-024 | B25: Nuoto | C25: Attivazione | D25: Velocità | E25: B1 | F25: 4x50 stile principale build-up | G25: 4x50 scelta stile principale, crescente nella vasca [B1] rec 20" | H25: A scelta | I25: Ragazzi, Assoluti | K25: =SUMPRODUCT((Parti!$A$2:$A$3000=A25)*Parti!$C$2:$C$3000*Parti!$D$2:$D$3000*Parti!$E$2:$E$3000) -> 200 | L25: =ROUND((K25*Legenda!$H$2/100+SUMPRODUCT((Parti!$A$2:$A$3000=A25)*Parti!$C$2:$C$3000*Parti!$D$2:$D$3000*(Parti!$F$2:$F$3000+Parti!$J$2:$J$3000)))/60,0) -> 5 | N25: approvato | O25: Libreria base
A26: N-025 | B26: Entrambi | C26: Attivazione | D26: Velocità | E26: V | F26: 8x25 12,5 veloce + 12,5 facile | G26: 8x25 scelta 12,5 m veloce + 12,5 m facile [V] rec 20" | H26: A scelta | I26: Esordienti, Ragazzi, Assoluti, Master | K26: =SUMPRODUCT((Parti!$A$2:$A$3000=A26)*Parti!$C$2:$C$3000*Parti!$D$2:$D$3000*Parti!$E$2:$E$3000) -> 200 | L26: =ROUND((K26*Legenda!$H$2/100+SUMPRODUCT((Parti!$A$2:$A$3000=A26)*Parti!$C$2:$C$3000*Parti!$D$2:$D$3000*(Parti!$F$2:$F$3000+Parti!$J$2:$J$3000)))/60,0) -> 6 | N26: approvato | O26: Libreria base
A27: N-026 | B27: Entrambi | C27: Attivazione | D27: Velocità | E27: B2 | F27: 4x(25 veloce + 25 facile) | G27: 4x50 scelta 25 veloce + 25 facile [B2] rec 15" | H27: A scelta | I27: Ragazzi, Assoluti, Master | K27: =SUMPRODUCT((Parti!$A$2:$A$3000=A27)*Parti!$C$2:$C$3000*Parti!$D$2:$D$3000*Parti!$E$2:$E$3000) -> 200 | L27: =ROUND((K27*Legenda!$H$2/100+SUMPRODUCT((Parti!$A$2:$A$3000=A27)*Parti!$C$2:$C$3000*Parti!$D$2:$D$3000*(Parti!$F$2:$F$3000+Parti!$J$2:$J$3000)))/60,0) -> 5 | N27: approvato | O27: Libreria base
A28: N-027 | B28: Nuoto | C28: Attivazione | D28: Velocità | E28: V | F28: 6x15 partenza dal blocco | G28: 6x15 scelta partenza dal blocco, uscita e prime bracciate [V] rec 45" | H28: A scelta | I28: Ragazzi, Assoluti | K28: =SUMPRODUCT((Parti!$A$2:$A$3000=A28)*Parti!$C$2:$C$3000*Parti!$D$2:$D$3000*Parti!$E$2:$E$3000) -> 90 | L28: =ROUND((K28*Legenda!$H$2/100+SUMPRODUCT((Parti!$A$2:$A$3000=A28)*Parti!$C$2:$C$3000*Parti!$D$2:$D$3000*(Parti!$F$2:$F$3000+Parti!$J$2:$J$3000)))/60,0) -> 6 | N28: approvato | O28: Libreria base
A29: N-028 | B29: Nuoto | C29: Attivazione | D29: Velocità | E29: V | F29: 6x15 uscite subacquee | G29: 6x15 DF ondulazioni subacquee fino a 10-15 m [V] rec 40" | H29: Delfino | I29: Ragazzi, Assoluti | K29: =SUMPRODUCT((Parti!$A$2:$A$3000=A29)*Parti!$C$2:$C$3000*Parti!$D$2:$D$3000*Parti!$E$2:$E$3000) -> 90 | L29: =ROUND((K29*Legenda!$H$2/100+SUMPRODUCT((Parti!$A$2:$A$3000=A29)*Parti!$C$2:$C$3000*Parti!$D$2:$D$3000*(Parti!$F$2:$F$3000+Parti!$J$2:$J$3000)))/60,0) -> 6 | N29: approvato | O29: Libreria base
A30: N-029 | B30: Nuoto | C30: Attivazione | D30: Velocità | E30: RG | F30: 4x25 ritmo gara | G30: 4x25 scelta ritmo gara della distanza obiettivo [RG] rec 40" | H30: A scelta | I30: Ragazzi, Assoluti | K30: =SUMPRODUCT((Parti!$A$2:$A$3000=A30)*Parti!$C$2:$C$3000*Parti!$D$2:$D$3000*Parti!$E$2:$E$3000) -> 100 | L30: =ROUND((K30*Legenda!$H$2/100+SUMPRODUCT((Parti!$A$2:$A$3000=A30)*Parti!$C$2:$C$3000*Parti!$D$2:$D$3000*(Parti!$F$2:$F$3000+Parti!$J$2:$J$3000)))/60,0) -> 5 | N30: approvato | O30: Libreria base
... A34: N-033 | B34: Entrambi | C34: Tecnica | D34: Tecnica | E34: T | F34: SL esordienti: braccio singolo, l'altro avanti | G34: 6x25 SL braccio singolo, l'altro avanti [T] rec 20" | H34: Stile libero | I34: Esordienti | K34: =SUMPRODUCT((Parti!$A$2:$A$3000=A34)*Parti!$C$2:$C$3000*Parti!$D$2:$D$3000*Parti!$E$2:$E$3000) -> 150 | L34: =ROUND((K34*Legenda!$H$2/100+SUMPRODUCT((Parti!$A$2:$A$3000=A34)*Parti!$C$2:$C$3000*Parti!$D$2:$D$3000*(Parti!$F$2:$F$3000+Parti!$J$2:$J$3000)))/60,0) -> 5 | N34: approvato | O34: Libreria base
A35: N-034 | B35: Nuoto | C35: Tecnica | D35: Tecnica | E35: T | F35: SL: 6 battute di lato + bracciata (rotazione) | G35: 6x50 SL 25 6 battute di lato + bracciata (rotazione) + 25 nuotato [T] rec 15" (Pinne) | H35: Stile libero | I35: Ragazzi, Assoluti, Master | J35: Pinne | K35: =SUMPRODUCT((Parti!$A$2:$A$3000=A35)*Parti!$C$2:$C$3000*Parti!$D$2:$D$3000*Parti!$E$2:$E$3000) -> 300 | L35: =ROUND((K35*Legenda!$H$2/100+SUMPRODUCT((Parti!$A$2:$A$3000=A35)*Parti!$C$2:$C$3000*Parti!$D$2:$D$3000*(Parti!$F$2:$F$3000+Parti!$J$2:$J$3000)))/60,0) -> 7 | N35: approvato | O35: Libreria base
A36: N-035 | B36: Nuoto | C36: Tecnica | D36: Tecnica | E36: T | F36: SL esordienti: 6 battute di lato + bracciata (rotazione) | G36: 6x25 SL 6 battute di lato + bracciata (rotazione) [T] rec 20" (Pinne) | H36: Stile libero | I36: Esordienti | J36: Pinne | K36: =SUMPRODUCT((Parti!$A$2:$A$3000=A36)*Parti!$C$2:$C$3000*Parti!$D$2:$D$3000*Parti!$E$2:$E$3000) -> 150 | L36: =ROUND((K36*Legenda!$H$2/100+SUMPRODUCT((Parti!$A$2:$A$3000=A36)*Parti!$C$2:$C$3000*Parti!$D$2:$D$3000*(Parti!$F$2:$F$3000+Parti!$J$2:$J$3000)))/60,0) -> 5 | N36: approvato | O36: Libreria base
A37: N-036 | B37: Nuoto | C37: Tecnica | D37: Tecnica | E37: T | F37: SL: zip: dita che sfiorano il fianco | G37: 6x50 SL 25 zip: dita che sfiorano il fianco + 25 nuotato [T] rec 15" | H37: Stile libero | I37: Ragazzi, Assoluti, Master | K37: =SUMPRODUCT((Parti!$A$2:$A$3000=A37)*Parti!$C$2:$C$3000*Parti!$D$2:$D$3000*Parti!$E$2:$E$3000) -> 300 | L37: =ROUND((K37*Legenda!$H$2/100+SUMPRODUCT((Parti!$A$2:$A$3000=A37)*Parti!$C$2:$C$3000*Parti!$D$2:$D$3000*(Parti!$F$2:$F$3000+Parti!$J$2:$J$3000)))/60,0) -> 7 | N37: approvato | O37: Libreria base
A38: N-037 | B38: Nuoto | C38: Tecnica | D38: Tecnica | E38: T | F38: SL esordienti: zip: dita che sfiorano il fianco | G38: 6x25 SL zip: dita che sfiorano il fianco [T] rec 20" | H38: Stile libero | I38: Esordienti | K38: =SUMPRODUCT((Parti!$A$2:$A$3000=A38)*Parti!$C$2:$C$3000*Parti!$D$2:$D$3000*Parti!$E$2:$E$3000) -> 150 | L38: =ROUND((K38*Legenda!$H$2/100+SUMPRODUCT((Parti!$A$2:$A$3000=A38)*Parti!$C$2:$C$3000*Parti!$D$2:$D$3000*(Parti!$F$2:$F$3000+Parti!$J$2:$J$3000)))/60,0) -> 5 | N38: approvato | O38: Libreria base
A39: N-038 | B39: Nuoto | C39: Tecnica | D39: Tecnica | E39: T | F39: SL: pugni chiusi | G39: 6x50 SL 25 pugni chiusi + 25 nuotato [T] rec 15" | H39: Stile libero | I39: Ragazzi, Assoluti, Master | K39: =SUMPRODUCT((Parti!$A$2:$A$3000=A39)*Parti!$C$2:$C$3000*Parti!$D$2:$D$3000*Parti!$E$2:$E$3000) -> 300 | L39: =ROUND((K39*Legenda!$H$2/100+SUMPRODUCT((Parti!$A$2:$A$3000=A39)*Parti!$C$2:$C$3000*Parti!$D$2:$D$3000*(Parti!$F$2:$F$3000+Parti!$J$2:$J$3000)))/60,0) -> 7 | N39: approvato | O39: Libreria base
A40: N-039 | B40: Nuoto | C40: Tecnica | D40: Tecnica | E40: T | F40: SL esordienti: pugni chiusi | G40: 6x25 SL pugni chiusi [T] rec 20" | H40: Stile libero | I40: Esordienti | K40: =SUMPRODUCT((Parti!$A$2:$A$3000=A40)*Parti!$C$2:$C$3000*Parti!$D$2:$D$3000*Parti!$E$2:$E$3000) -> 150 | L40: =ROUND((K40*Legenda!$H$2/100+SUMPRODUCT((Parti!$A$2:$A$3000=A40)*Parti!$C$2:$C$3000*Parti!$D$2:$D$3000*(Parti!$F$2:$F$3000+Parti!$J$2:$J$3000)))/60,0) -> 5 | N40: approvato | O40: Libreria base
A41: N-040 | B41: Nuoto | C41: Tecnica | D41: Tecnica | E41: T | F41: SL: respirazione bilaterale ogni 3 | G41: 6x50 SL 25 respirazione bilaterale ogni 3 + 25 nuotato [T] rec 15" | H41: Stile libero | I41: Ragazzi, Assoluti, Master | K41: =SUMPRODUCT((Parti!$A$2:$A$3000=A41)*Parti!$C$2:$C$3000*Parti!$D$2:$D$3000*Parti!$E$2:$E$3000) -> 300 | L41: =ROUND((K41*Legenda!$H$2/100+SUMPRODUCT((Parti!$A$2:$A$3000=A41)*Parti!$C$2:$C$3000*Parti!$D$2:$D$3000*(Parti!$F$2:$F$3000+Parti!$J$2:$J$3000)))/60,0) -> 7 | N41: approvato | O41: Libreria base
A42: N-041 | B42: Nuoto | C42: Tecnica | D42: Tecnica | E42: T | F42: SL esordienti: respirazione bilaterale ogni 3 | G42: 6x25 SL respirazione bilaterale ogni 3 [T] rec 20" | H42: Stile libero | I42: Esordienti | K42: =SUMPRODUCT((Parti!$A$2:$A$3000=A42)*Parti!$C$2:$C$3000*Parti!$D$2:$D$3000*Parti!$E$2:$E$3000) -> 150 | L42: =ROUND((K42*Legenda!$H$2/100+SUMPRODUCT((Parti!$A$2:$A$3000=A42)*Parti!$C$2:$C$3000*Parti!$D$2:$D$3000*(Parti!$F$2:$F$3000+Parti!$J$2:$J$3000)))/60,0) -> 5 | N42: approvato | O42: Libreria base
A43: N-042 | B43: Entrambi | C43: Tecnica | D43: Tecnica | E43: T | F43: SL: testa alta (stile pallanuoto) | G43: 6x50 SL 25 testa alta (stile pallanuoto) + 25 nuotato [T] rec 15" | H43: Stile libero | I43: Ragazzi, Assoluti, Master | K43: =SUMPRODUCT((Parti!$A$2:$A$3000=A43)*Parti!$C$2:$C$3000*Parti!$D$2:$D$3000*Parti!$E$2:$E$3000) -> 300 | L43: =ROUND((K43*Legenda!$H$2/100+SUMPRODUCT((Parti!$A$2:$A$3000=A43)*Parti!$C$2:$C$3000*Parti!$D$2:$D$3000*(Parti!$F$2:$F$3000+Parti!$J$2:$J$3000)))/60,0) -> 7 | N43: approvato | O43: Libreria base
...

Sheet Legenda
A1: Zona | B1: Nome | C1: Sensazione | D1: Recupero tipico (s) | E1: Riferimento di passo | G1: Parametro | H1: Valore | J1: Sport | K1: Fase | L1: Obiettivo | M1: Stile | N1: Stato | O1: Zona
A2: A1 | B2: Aerobico leggero / recupero | C2: Facile, si parla | D2: 10-20 | E2: CSS + 10-15" | G2: Passo medio per stimare la durata (s per 100 m) | H2: 110 | J2: Nuoto | K2: A secco | L2: Aerobico | M2: Stile libero | N2: approvato | O2: A1
A3: A2 | B3: Aerobico medio (capacità aerobica) | C3: Ritmo regolare e sostenibile | D3: 10-20 | E3: CSS + 5-8" | G3: Valore ipotizzato (comprende virate e cambi di ritmo): cambialo in base al tuo gruppo. | J3: Pallanuoto | K3: Attacco | L3: Attivazione | M3: Dorso | N3: bozza | O3: A2
A4: B1 | B4: Soglia anaerobica | C4: Impegnativo ma costante | D4: 10-30 | E4: CSS ± 2" | J4: Entrambi | K4: Attivazione | L4: Forza | M4: Rana | O4: B1
A5: B2 | B5: Massimo consumo di ossigeno (VO2max) | C5: Forte | D5: 30-60 | E5: CSS - 2/4" | K5: Braccia | L5: Lattacido | M5: Delfino | O5: B2
A6: C1 | B6: Tolleranza / capacità lattacida | C6: Molto forte, vicino al ritmo gara | D6: 60-120 | E6: Ritmo gara 200-400 | K6: Condizionamento | L6: Recupero | M6: Misti | O6: C1
A7: C2 | B7: Potenza lattacida | C7: Massimale | D7: 180-300 | E7: Massimale 50-100 | K7: Defaticamento | L7: Ritmo gara | M7: A scelta | O7: C2
A8: V | B8: Velocità alattacida | C8: Sprint massimale breve | D8: 45-90 | E8: Massimale 10-25 m | K8: Difesa | L8: Soglia | M8: Testa alta | O8: V
A9: RG | B9: Ritmo gara | C9: Passo della gara obiettivo | D9: variabile | E9: Passo gara | K9: Gambe | L9: Tattica | M9: Dorso polo | O9: RG
A10: T | B10: Tecnica | C10: Qualità del gesto, senza tempo | D10: 15-30 | E10: — | K10: Nuoto specifico | L10: Tecnica | O10: T
A11: TT | B11: Tecnico-tattico (pallanuoto) | C11: Esercitazioni di gioco | D11: — | E11: — | K11: Partita a tema | L11: Test | O11: TT
A12: TEST | B12: Test | C12: Prova di valutazione | D12: — | E12: — | K12: Passaggi | L12: VO2max | O12: TEST
K13: Portiere | L13: Velocità
A14: Valori indicativi, modificabili. CSS = velocità critica dal test 400+200. | K14: Riscaldamento
K15: Serie principale
K16: Tecnica
K17: Test
K18: Tiro

Sheet Parti
A1: ID blocco | B1: Ordine | C1: Giri | D1: Ripetizioni | E1: Distanza (m) | F1: Durata (s) | G1: Stile | H1: Esercizio / andatura | I1: Zona | J1: Recupero (s) | K1: Attrezzi | L1: Note
A2: N-001 | B2: 1 | C2: 1 | D2: 1 | E2: 200 | G2: Stile libero | H2: sciolto | I2: A1
A3: N-001 | B3: 2 | C3: 1 | D3: 1 | E3: 100 | G3: Dorso | H3: sciolto | I3: A1
A4: N-001 | B4: 3 | C4: 1 | D4: 1 | E4: 100 | G4: Rana | H4: sciolto | I4: A1
A5: N-002 | B5: 1 | C5: 1 | D5: 3 | E5: 100 | G5: Stile libero | H5: respirazione ogni 3-5-7 bracciate per 25 | I5: A1 | J5: 10
A6: N-003 | B6: 1 | C6: 1 | D6: 8 | E6: 50 | G6: Misti | H6: 25 stile + 25 stile successivo, ordine inverso | I6: A1 | J6: 15
A7: N-004 | B7: 1 | C7: 1 | D7: 1 | E7: 200 | G7: Stile libero | I7: A1 | J7: 20
A8: N-004 | B8: 2 | C8: 1 | D8: 1 | E8: 200 | G8: Dorso | I8: A1 | J8: 20
A9: N-004 | B9: 3 | C9: 1 | D9: 1 | E9: 200 | G9: Misti | H9: sciolto | I9: A1
A10: N-005 | B10: 1 | C10: 1 | D10: 4 | E10: 100 | G10: Stile libero | H10: progressivo per 100 (da A1 ad A2) | I10: A1 | J10: 10
A11: N-006 | B11: 1 | C11: 1 | D11: 1 | E11: 200 | G11: Stile libero | I11: A1 | J11: 20
A12: N-006 | B12: 2 | C12: 1 | D12: 4 | E12: 50 | G12: A scelta | H12: gambe | I12: A1 | J12: 15 | K12: Tavoletta
A13: N-006 | B13: 3 | C13: 1 | D13: 4 | E13: 50 | G13: Stile libero | H13: braccia | I13: A1 | J13: 15 | K13: Pull buoy
A14: N-007 | B14: 1 | C14: 1 | D14: 1 | E14: 100 | G14: Stile libero | I14: A1 | J14: 20
A15: N-007 | B15: 2 | C15: 1 | D15: 1 | E15: 100 | G15: Dorso | I15: A1 | J15: 20
A16: N-007 | B16: 3 | C16: 1 | D16: 4 | E16: 25 | G16: A scelta | H16: tecnica a scelta | I16: A1 | J16: 20
A17: N-008 | B17: 1 | C17: 1 | D17: 4 | E17: 50 | G17: Misti | H17: 25 dorso + 25 SL | I17: A1 | J17: 20
A18: N-009 | B18: 1 | C18: 1 | D18: 1 | E18: 300 | G18: A scelta | H18: sciolto | I18: A1 | J18: 30
A19: N-009 | B19: 2 | C19: 1 | D19: 4 | E19: 50 | G19: Misti | H19: sciolto | I19: A1 | J19: 20
A20: N-010 | B20: 1 | C20: 1 | D20: 4 | E20: 100 | G20: Misti | H20: 50 SL + 50 stile del giorno | I20: A1 | J20: 15
A21: N-011 | B21: 1 | C21: 1 | D21: 1 | E21: 200 | G21: Stile libero | I21: A1
A22: N-011 | B22: 2 | C22: 1 | D22: 1 | E22: 200 | G22: Dorso | I22: A1
A23: N-011 | B23: 3 | C23: 1 | D23: 1 | E23: 200 | G23: A scelta | H23: gambe | I23: A1 | K23: Pinne
A24: N-011 | B24: 4 | C24: 1 | D24: 1 | E24: 200 | G24: Stile libero | I24: A1
A25: N-012 | B25: 1 | C25: 1 | D25: 6 | E25: 100 | G25: Misti | H25: dispari SL, pari dorso, progressivo per serie | I25: A1 | J25: 15
A26: N-013 | B26: 1 | C26: 1 | D26: 1 | E26: 200 | G26: Stile libero | I26: A1 | J26: 20
A27: N-013 | B27: 2 | C27: 1 | D27: 4 | E27: 50 | G27: Rana | H27: 2 gambate 1 bracciata | I27: A1 | J27: 15
A28: N-013 | B28: 3 | C28: 1 | D28: 4 | E28: 50 | G28: Rana | H28: nuotato | I28: A1 | J28: 15
A29: N-014 | B29: 1 | C29: 1 | D29: 1 | E29: 300 | G29: Stile libero | I29: A1 | J29: 20
A30: N-014 | B30: 2 | C30: 1 | D30: 6 | E30: 25 | G30: Delfino | H30: braccio singolo dx/sx | I30: A1 | J30: 15 | K30: Pinne
A31: N-014 | B31: 3 | C31: 1 | D31: 4 | E31: 25 | G31: Delfino | H31: nuotato | I31: A1 | J31: 20
A32: N-015 | B32: 1 | C32: 1 | D32: 1 | E32: 200 | G32: Stile libero | I32: A1 | J32: 20
A33: N-015 | B33: 2 | C33: 1 | D33: 4 | E33: 50 | G33: Dorso | H33: braccio singolo / doppio braccio | I33: A1 | J33: 15
A34: N-015 | B34: 3 | C34: 1 | D34: 4 | E34: 50 | G34: Dorso | H34: nuotato | I34: A1 | J34: 15
A35: N-016 | B35: 1 | C35: 1 | D35: 1 | E35: 400 | G35: A scelta | H35: sciolto | I35: A1 | J35: 30
A36: N-016 | B36: 2 | C36: 1 | D36: 4 | E36: 50 | G36: Stile libero | H36: progressivi | I36: A2 | J36: 20
A37: N-016 | B37: 3 | C37: 1 | D37: 4 | E37: 25 | G37: A scelta | H37: ritmo gara | I37: RG | J37: 40
A38: N-016 | B38: 4 | C38: 1 | D38: 2 | E38: 15 | G38: A scelta | H38: sprint dal blocco | I38: V | J38: 60
A39: N-017 | B39: 1 | C39: 1 | D39: 1 | E39: 400 | G39: Misti | H39: 100 SL + 100 dorso + 100 delfino-ondulazioni + 100 SL | I39: A1 | K39: Pinne
A40: N-018 | B40: 1 | C40: 1 | D40: 6 | E40: 25 | G40: Stile libero | H40: progressivi nella serie | I40: B1 | J40: 20
...
